<?xml version="1.0"?>
<robot xmlns:xacro="http://www.ros.org/wiki/xacro">

    <xacro:include filename="inertial_macros.xacro" />
    <xacro:include filename="omegabot_body.xacro" />
    <xacro:include filename="omegabot_wheel.xacro" />


    <link name="base_link" />


    <joint name="body_joint" type="fixed">
        <parent link="base_link" />
        <child link="body" />
        <origin xyz="0 0 0" />
    </joint>

    <xacro:omegabot_body name="body" />


    <joint name="front_left_wheel_joint" type="continuous">
        <parent link="base_link" />
        <child link="front_left_wheel" />
        <origin xyz="0.057 0.05 0" rpy="-${pi/2} 0 0" />
        <axis xyz="0 0 1" />
    </joint>

    <xacro:omegabot_wheel name="front_left_wheel" />


    <joint name="front_right_wheel_joint" type="continuous">
        <parent link="base_link" />
        <child link="front_right_wheel" />
        <origin xyz="0.057 -0.05 0" rpy="${pi/2} 0 0" />
        <axis xyz="0 0 -1" />
    </joint>

    <xacro:omegabot_wheel name="front_right_wheel" />


    <joint name="rear_left_wheel_joint" type="continuous">
        <parent link="base_link" />
        <child link="rear_left_wheel" />
        <origin xyz="-0.057 0.05 0" rpy="-${pi/2} 0 0" />
        <axis xyz="0 0 1" />
    </joint>

    <xacro:omegabot_wheel name="rear_left_wheel" />


    <joint name="rear_right_wheel_joint" type="continuous">
        <parent link="base_link" />
        <child link="rear_right_wheel" />
        <origin xyz="-0.057 -0.05 0" rpy="${pi/2} 0 0" />
        <axis xyz="0 0 -1" />
    </joint>

    <xacro:omegabot_wheel name="rear_right_wheel" />

</robot>